<?xml version="1.0" ?>
<robot xmlns:xacro="http://ros.org/wiki/xacro">

<xacro:macro name="wheel" params="name:=wheel parent:=base_link radius width *origin">

  <xacro:include filename="$(find ca_description)/urdf/common_properties.xacro"/>

  <xacro:property name="parent_link" value="${parent}"/>
  <xacro:property name="link_name"   value="${name}_link"/>

  <xacro:property name="mass"        value="0.1"/>

  <joint name="${name}_joint" type="continuous">
    <xacro:insert_block name="origin"/>
    <parent link="${parent_link}" />
    <child link="${link_name}" />
    <axis xyz="0 1 0" />
  </joint>

  <link name="${link_name}">
    <xacro:inertial_cylinder mass="${mass}" radius="${radius}" length="${width}"/>

    <visual>
      <geometry>
        <cylinder radius="${radius}" length="${width}" />
      </geometry>
    </visual>

    <collision>
      <geometry>
        <cylinder radius="${radius}" length="${width}" />
      </geometry>
    </collision>
  </link>

</xacro:macro>

</robot>
